Workbook

Sheet Report
B1: Top 10 Dman pairs in 2022/23 season based on icetime
B138: D-man comparision
D139: Middleton-Spurgeon | H139: =VLOOKUP(D139,'D-man top 10'!$A$2:$B$11,2,FALSE) -> MIN | L139: Dunn-Larsson | P139: =VLOOKUP(L139,'D-man top 10'!$A$2:$B$11,2,FALSE) -> SEA
D140: games_played | H140: =VLOOKUP($D$139,'D-man top 10'!$A$123:$AB$133,3,FALSE) -> 76 | L140: games_played | P140: =VLOOKUP($L$139,'D-man top 10'!$A$123:$AB$133,3,FALSE) -> 81
D141: time on the ice | H141: =VLOOKUP($D$139,'D-man top 10'!$A$123:$AB$133,4,FALSE) -> 0.70878472 | L141: time on the ice | P141: =VLOOKUP($L$139,'D-man top 10'!$A$123:$AB$133,4,FALSE) -> 0.95334491
D142: shotsattemptsfor | H142: =VLOOKUP($D$139,'D-man top 10'!$A$123:$AB$133,5,FALSE) -> 976 | L142: shotsattemptsfor | P142: =VLOOKUP($L$139,'D-man top 10'!$A$123:$AB$133,5,FALSE) -> 1377
D143: shotsongoalfor | H143: =VLOOKUP($D$139,'D-man top 10'!$A$123:$AB$133,6,FALSE) -> 476 | L143: shotsongoalfor | P143: =VLOOKUP($L$139,'D-man top 10'!$A$123:$AB$133,6,FALSE) -> 701
D144: missedshotsfor | H144: =VLOOKUP($D$139,'D-man top 10'!$A$123:$AB$133,7,FALSE) -> 240 | L144: missedshotsfor | P144: =VLOOKUP($L$139,'D-man top 10'!$A$123:$AB$133,7,FALSE) -> 335
D145: blockedshotattemptsfor | H145: =VLOOKUP($D$139,'D-man top 10'!$A$123:$AB$133,8,FALSE) -> 260 | L145: blockedshotattemptsfor | P145: =VLOOKUP($L$139,'D-man top 10'!$A$123:$AB$133,8,FALSE) -> 341
D146: shotattemptsagainst | H146: =VLOOKUP($D$139,'D-man top 10'!$A$123:$AB$133,9,FALSE) -> 985 | L146: shotattemptsagainst | P146: =VLOOKUP($L$139,'D-man top 10'!$A$123:$AB$133,9,FALSE) -> 1148
D147: shotsongoalagainst | H147: =VLOOKUP($D$139,'D-man top 10'!$A$123:$AB$133,10,FALSE) -> 474 | L147: shotsongoalagainst | P147: =VLOOKUP($L$139,'D-man top 10'!$A$123:$AB$133,10,FALSE) -> 608
D148: missedshotsagainst | H148: =VLOOKUP($D$139,'D-man top 10'!$A$123:$AB$133,11,FALSE) -> 201 | L148: missedshotsagainst | P148: =VLOOKUP($L$139,'D-man top 10'!$A$123:$AB$133,11,FALSE) -> 241
D149: blokedshotattemptsagainst | H149: =VLOOKUP($D$139,'D-man top 10'!$A$123:$AB$133,12,FALSE) -> 310 | L149: blokedshotattemptsagainst | P149: =VLOOKUP($L$139,'D-man top 10'!$A$123:$AB$133,12,FALSE) -> 299
D150: penaltiesfor | H150: =VLOOKUP($D$139,'D-man top 10'!$A$123:$AB$133,13,FALSE) -> 63 | L150: penaltiesfor | P150: =VLOOKUP($L$139,'D-man top 10'!$A$123:$AB$133,13,FALSE) -> 77
D151: penalityminutesfor | H151: =VLOOKUP($D$139,'D-man top 10'!$A$123:$AB$133,14,FALSE) -> 150 | L151: penalityminutesfor | P151: =VLOOKUP($L$139,'D-man top 10'!$A$123:$AB$133,14,FALSE) -> 166
D152: penaltiesagainst | H152: =VLOOKUP($D$139,'D-man top 10'!$A$123:$AB$133,15,FALSE) -> 66 | L152: penaltiesagainst | P152: =VLOOKUP($L$139,'D-man top 10'!$A$123:$AB$133,15,FALSE) -> 84
D153: penalityminutesagainst | H153: =VLOOKUP($D$139,'D-man top 10'!$A$123:$AB$133,16,FALSE) -> 156 | L153: penalityminutesagainst | P153: =VLOOKUP($L$139,'D-man top 10'!$A$123:$AB$133,16,FALSE) -> 186
D154: lowdangershotsfor | H154: =VLOOKUP($D$139,'D-man top 10'!$A$123:$AB$133,17,FALSE) -> 535 | L154: lowdangershotsfor | P154: =VLOOKUP($L$139,'D-man top 10'!$A$123:$AB$133,17,FALSE) -> 777
D155: mediumdangershotsfor | H155: =VLOOKUP($D$139,'D-man top 10'!$A$123:$AB$133,18,FALSE) -> 147 | L155: mediumdangershotsfor | P155: =VLOOKUP($L$139,'D-man top 10'!$A$123:$AB$133,18,FALSE) -> 205
D156: highdangershotsfor | H156: =VLOOKUP($D$139,'D-man top 10'!$A$123:$AB$133,19,FALSE) -> 34 | L156: highdangershotsfor | P156: =VLOOKUP($L$139,'D-man top 10'!$A$123:$AB$133,19,FALSE) -> 54
D157: lowdangershotsagainst | H157: =VLOOKUP($D$139,'D-man top 10'!$A$123:$AB$133,20,FALSE) -> 529 | L157: lowdangershotsagainst | P157: =VLOOKUP($L$139,'D-man top 10'!$A$123:$AB$133,20,FALSE) -> 609
D158: mediumdangershotsagainst | H158: =VLOOKUP($D$139,'D-man top 10'!$A$123:$AB$133,21,FALSE) -> 125 | L158: mediumdangershotsagainst | P158: =VLOOKUP($L$139,'D-man top 10'!$A$123:$AB$133,21,FALSE) -> 178
D159: highdangershotsagainst | H159: =VLOOKUP($D$139,'D-man top 10'!$A$123:$AB$133,22,FALSE) -> 21 | L159: highdangershotsagainst | P159: =VLOOKUP($L$139,'D-man top 10'!$A$123:$AB$133,22,FALSE) -> 62
D160: xgoalsfor | H160: =VLOOKUP($D$139,'D-man top 10'!$A$123:$AB$133,23,FALSE) -> 42.27 | L160: xgoalsfor | P160: =VLOOKUP($L$139,'D-man top 10'!$A$123:$AB$133,23,FALSE) -> 63.92
D161: xgoalsagainst | H161: =VLOOKUP($D$139,'D-man top 10'!$A$123:$AB$133,24,FALSE) -> 36.82 | L161: xgoalsagainst | P161: =VLOOKUP($L$139,'D-man top 10'!$A$123:$AB$133,24,FALSE) -> 57.35
D162: goalsfor | H162: =VLOOKUP($D$139,'D-man top 10'!$A$123:$AB$133,25,FALSE) -> 43 | L162: goalsfor | P162: =VLOOKUP($L$139,'D-man top 10'!$A$123:$AB$133,25,FALSE) -> 80
D163: goalsagainst | H163: =VLOOKUP($D$139,'D-man top 10'!$A$123:$AB$133,26,FALSE) -> 28 | L163: goalsagainst | P163: =VLOOKUP($L$139,'D-man top 10'!$A$123:$AB$133,26,FALSE) -> 60
D164: goalsfor/60 | H164: =VLOOKUP($D$139,'D-man top 10'!$A$123:$AB$133,27,FALSE) -> 2.5278009 | L164: goalsfor/60 | P164: =VLOOKUP($L$139,'D-man top 10'!$A$123:$AB$133,27,FALSE) -> 3.496461
D165: goalsagainst/60 | H165: =VLOOKUP($D$139,'D-man top 10'!$A$123:$AB$133,28,FALSE) -> 1.6460099 | L165: goalsagainst/60 | P165: =VLOOKUP($L$139,'D-man top 10'!$A$123:$AB$133,28,FALSE) -> 2.6223458
B166: Legenda:
B167: games_played | F167: Number of games a player or team has participated in.
B168: time on the ice | F168: Total minutes a player spends playing during games.
B169: shotsattemptsfor | F169: Total shot attempts made by the team (including on goal)
B170: shotsongoalfor | F170: Shots directed at the opponent’s net that required a save or scored.
B171: missedshotsfor | F171: Shot attempts that missed the opponent’s net completely.
B172: blockedshotattemptsfor | F172: Shot attempts blocked by opposing players before reaching the net.
B173: shotattemptsagainst | F173: Total shot attempts made by the opponent team.
B174: shotsongoalagainst | F174: Shots by opponents that reached the net and required a save or scored.
B175: missedshotsagainst | F175: Opponent shot attempts that missed the net completely.
B176: blokedshotattemptsagainst | F176: Opponent shot attempts blocked by your team before reaching the net.
...

Sheet D-man top 10
A1: name | B1: team | C1: games_played | D1: icetime | E1: time (min, sec) | F1: corsipercentage | G1: fenwickpercentage | H1: shotsattemptsfor | I1: shotsongoalfor | J1: missedshotsfor | K1: blockedshotattemptsfor | L1: shotattemptsagainst | M1: shotsongoalagainst | N1: missedshotsagainst | O1: blokedshotattemptsagainst | P1: penaltiesfor | Q1: penalityminutesfor | R1: penaltiesagainst | S1: penalityminutesagainst | T1: lowdangershotsfor | U1: mediumdangershotsfor | V1: highdangershotsfor | W1: lowdangershotsagainst | X1: mediumdangershotsagainst | Y1: highdangershotsagainst | Z1: xgoalsfor | AA1: xgoalsagainst | AB1: goalsfor | AC1: goalsagainst | AD1: goalsfor/60 | AE1: goalsagainst/60
A2: Dunn-Larsson | B2: SEA | C2: 81 | D2: 82369 | E2: =INT(D2/60) & " min " & MOD(D2,60) & " s" -> 1372 min 49 s | F2: 0.55 | G2: 0.55 | H2: =SUM(I2:K2) -> 1377 | I2: 701 | J2: 335 | K2: 341 | L2: 1148 | M2: 608 | N2: 241 | O2: =L2-M2-N2 -> 299 | P2: 77 | Q2: 166 | R2: 84 | S2: 186 | T2: 777 | U2: 205 | V2: 54 | W2: 609 | X2: 178 | Y2: 62 | Z2: 63.92 | AA2: 57.35 | AB2: 80 | AC2: 60 | AD2: =(AB2/D2)*3600 -> 3.496461 | AE2: =(AC2/D2)*3600 -> 2.6223458
A3: Anderson-Doughty | B3: LAK | C3: 76 | D3: 78733 | E3: =INT(D3/60) & " min " & MOD(D3,60) & " s" -> 1312 min 13 s | F3: 0.53 | G3: 0.53 | H3: =SUM(I3:K3) -> 1163 | I3: 633 | J3: 240 | K3: 290 | L3: 1047 | M3: 542 | N3: 232 | O3: =L3-M3-N3 -> 273 | P3: 72 | Q3: 161 | R3: 97 | S3: 202 | T3: 634 | U3: 180 | V3: 59 | W3: 543 | X3: 180 | Y3: 51 | Z3: 57.62 | AA3: 52.24 | AB3: 53 | AC3: 44 | AD3: =(AB3/D3)*3600 -> 2.4233803 | AE3: =(AC3/D3)*3600 -> 2.0118629
A4: Skjei-Pesce | B4: CAR | C4: 81 | D4: 78431 | E4: =INT(D4/60) & " min " & MOD(D4,60) & " s" -> 1307 min 11 s | F4: 0.59 | G4: 0.58 | H4: =SUM(I4:K4) -> 1430 | I4: 731 | J4: 352 | K4: 347 | L4: 1003 | M4: 571 | N4: 210 | O4: =L4-M4-N4 -> 222 | P4: 81 | Q4: 169 | R4: 82 | S4: 173 | T4: 817 | U4: 205 | V4: 61 | W4: 570 | X4: 166 | Y4: 45 | Z4: 65.21 | AA4: 48.88 | AB4: 56 | AC4: 49 | AD4: =(AB4/D4)*3600 -> 2.5704122 | AE4: =(AC4/D4)*3600 -> 2.2491107
A5: Slavin-Burns | B5: CAR | C5: 76 | D5: 71641 | E5: =INT(D5/60) & " min " & MOD(D5,60) & " s" -> 1194 min 1 s | F5: 0.62 | G5: 0.61 | H5: =SUM(I5:K5) -> 1474 | I5: 733 | J5: 357 | K5: 384 | L5: 903 | M5: 506 | N5: 202 | O5: =L5-M5-N5 -> 195 | P5: 74 | Q5: 151 | R5: 67 | S5: 136 | T5: 823 | U5: 197 | V5: 70 | W5: 524 | X5: 153 | Y5: 31 | Z5: 67.19 | AA5: 41.7 | AB5: 52 | AC5: 39 | AD5: =(AB5/D5)*3600 -> 2.6130289 | AE5: =(AC5/D5)*3600 -> 1.9597716
A6: Miller-Trouba | B6: NYR | C6: 79 | D6: 67202 | E6: =INT(D6/60) & " min " & MOD(D6,60) & " s" -> 1120 min 2 s | F6: 0.51 | G6: 0.52 | H6: =SUM(I6:K6) -> 1064 | I6: 564 | J6: 224 | K6: 276 | L6: 1003 | M6: 514 | N6: 208 | O6: =L6-M6-N6 -> 281 | P6: 65 | Q6: 136 | R6: 59 | S6: 124 | T6: 601 | U6: 151 | V6: 36 | W6: 515 | X6: 159 | Y6: 48 | Z6: 44.83 | AA6: 47.63 | AB6: 48 | AC6: 55 | AD6: =(AB6/D6)*3600 -> 2.571352 | AE6: =(AC6/D6)*3600 -> 2.9463409
A7: Nurse-Ceci | B7: EDM | C7: 80 | D7: 65060 | E7: =INT(D7/60) & " min " & MOD(D7,60) & " s" -> 1084 min 20 s | F7: 0.5 | G7: 0.49 | H7: =SUM(I7:K7) -> 999 | I7: 538 | J7: 211 | K7: 250 | L7: 986 | M7: 560 | N7: 206 | O7: =L7-M7-N7 -> 220 | P7: 84 | Q7: 182 | R7: 70 | S7: 152 | T7: 526 | U7: 184 | V7: 39 | W7: 569 | X7: 157 | Y7: 40 | Z7: 49.95 | AA7: 48.83 | AB7: 46 | AC7: 48 | AD7: =(AB7/D7)*3600 -> 2.5453428 | AE7: =(AC7/D7)*3600 -> 2.6560098
A8: Middleton-Spurgeon | B8: MIN | C8: 76 | D8: 61239 | E8: =INT(D8/60) & " min " & MOD(D8,60) & " s" -> 1020 min 39 s | F8: 0.5 | G8: 0.51 | H8: =SUM(I8:K8) -> 976 | I8: 476 | J8: 240 | K8: 260 | L8: 985 | M8: 474 | N8: 201 | O8: =L8-M8-N8 -> 310 | P8: 63 | Q8: 150 | R8: 66 | S8: 156 | T8: 535 | U8: 147 | V8: 34 | W8: 529 | X8: 125 | Y8: 21 | Z8: 42.27 | AA8: 36.82 | AB8: 43 | AC8: 28 | AD8: =(AB8/D8)*3600 -> 2.5278009 | AE8: =(AC8/D8)*3600 -> 1.6460099
A9: Siegenthaler-Hamilton | B9: NJD | C9: 78 | D9: 61153 | E9: =INT(D9/60) & " min " & MOD(D9,60) & " s" -> 1019 min 13 s | F9: 0.55 | G9: 0.55 | H9: =SUM(I9:K9) -> 1132 | I9: 615 | J9: 238 | K9: 279 | L9: 945 | M9: 482 | N9: 220 | O9: =L9-M9-N9 -> 243 | P9: 58 | Q9: 124 | R9: 55 | S9: 126 | T9: 655 | U9: 148 | V9: 50 | W9: 527 | X9: 138 | Y9: 37 | Z9: 51.55 | AA9: 41.31 | AB9: 61 | AC9: 38 | AD9: =(AB9/D9)*3600 -> 3.5909931 | AE9: =(AC9/D9)*3600 -> 2.2370121
A10: Leddy-Parayko | B10: STL | C10: 75 | D10: 59761 | E10: =INT(D10/60) & " min " & MOD(D10,60) & " s" -> 996 min 1 s | F10: 0.46 | G10: 0.46 | H10: =SUM(I10:K10) -> 792 | I10: 414 | J10: 174 | K10: 204 | L10: 928 | M10: 513 | N10: 182 | O10: =L10-M10-N10 -> 233 | P10: 54 | Q10: 111 | R10: 60 | S10: 125 | T10: 438 | U10: 119 | V10: 31 | W10: 512 | X10: 142 | Y10: 41 | Z10: 36.28 | AA10: 46.15 | AB10: 34 | AC10: 47 | AD10: =(AB10/D10)*3600 -> 2.0481585 | AE10: =(AC10/D10)*3600 -> 2.8312779
A11: Lindell-Hakanp | B11: DAL | C11: 82 | D11: 59505 | E11: =INT(D11/60) & " min " & MOD(D11,60) & " s" -> 991 min 45 s | F11: 0.47 | G11: 0.47 | H11: =SUM(I11:K11) -> 866 | I11: 456 | J11: 162 | K11: 248 | L11: 968 | M11: 499 | N11: 204 | O11: =L11-M11-N11 -> 265 | P11: 62 | Q11: 133 | R11: 59 | S11: 125 | T11: 442 | U11: 132 | V11: 44 | W11: 539 | X11: 127 | Y11: 37 | Z11: 40.86 | AA11: 40.57 | AB11: 42 | AC11: 38 | AD11: =(AB11/D11)*3600 -> 2.5409629 | AE11: =(AC11/D11)*3600 -> 2.2989665
A16: name | B16: team | C16: games_played | D16: time (min, sec) | E16: time on the ice | F16: name, team | G16: games_played | H16: time on the ice
A17: Dunn-Larsson | B17: SEA | C17: 81 | D17: 1372 min 49 s | E17: 0.95334491 | F17: Dunn-Larsson, SEA | G17: 81 | H17: 0.95334491
A18: Anderson-Doughty | B18: LAK | C18: 76 | D18: 1312 min 13 s | E18: 0.91126157 | F18: Anderson-Doughty, LAK | G18: 76 | H18: 0.91126157
A19: Skjei-Pesce | B19: CAR | C19: 81 | D19: 1307 min 11 s | E19: 0.9077662 | F19: Skjei-Pesce, CAR | G19: 81 | H19: 0.9077662
A20: Slavin-Burns | B20: CAR | C20: 76 | D20: 1194 min 1 s | E20: 0.82917824 | F20: Slavin-Burns, CAR | G20: 76 | H20: 0.82917824
A21: Miller-Trouba | B21: NYR | C21: 79 | D21: 1120 min 2 s | E21: 0.77780093 | F21: Miller-Trouba, NYR | G21: 79 | H21: 0.77780093
A22: Nurse-Ceci | B22: EDM | C22: 80 | D22: 1084 min 20 s | E22: 0.75300926 | F22: Nurse-Ceci, EDM | G22: 80 | H22: 0.75300926
A23: Middleton-Spurgeon | B23: MIN | C23: 76 | D23: 1020 min 39 s | E23: 0.70878472 | F23: Middleton-Spurgeon, MIN | G23: 76 | H23: 0.70878472
A24: Siegenthaler-Hamilton | B24: NJD | C24: 78 | D24: 1019 min 13 s | E24: 0.70778935 | F24: Siegenthaler-Hamilton, NJD | G24: 78 | H24: 0.70778935
A25: Leddy-Parayko | B25: STL | C25: 75 | D25: 996 min 1 s | E25: 0.69167824 | F25: Leddy-Parayko, STL | G25: 75 | H25: 0.69167824
A26: Lindell-Hakanp | B26: DAL | C26: 82 | D26: 991 min 45 s | E26: 0.68871528 | F26: Lindell-Hakanp, DAL | G26: 82 | H26: 0.68871528
A29: name | B29: team | C29: shotsattemptsfor | D29: shotsongoalfor | E29: missedshotsfor | F29: blockedshotattemptsfor | G29: shotsattemptsfor | H29: shotsongoalfor | I29: missedshotsfor | J29: blockedshotattemptsfor
A30: Slavin-Burns | B30: CAR | C30: =SUM(D30:F30) -> 1474 | D30: 733 | E30: 357 | F30: 384 | G30: 1 | H30: 0.4972863 | I30: 0.2421981 | J30: 0.2605156
A31: Skjei-Pesce | B31: CAR | C31: =SUM(D31:F31) -> 1430 | D31: 731 | E31: 352 | F31: 347 | G31: 1 | H31: 0.51118881 | I31: 0.24615385 | J31: 0.24265734
A32: Dunn-Larsson | B32: SEA | C32: =SUM(D32:F32) -> 1377 | D32: 701 | E32: 335 | F32: 341 | G32: 1 | H32: 0.50907771 | I32: 0.2432825 | J32: 0.2476398
A33: Anderson-Doughty | B33: LAK | C33: =SUM(D33:F33) -> 1163 | D33: 633 | E33: 240 | F33: 290 | G33: 1 | H33: 0.54428203 | I33: 0.20636285 | J33: 0.24935512
A34: Siegenthaler-Hamilton | B34: NJD | C34: =SUM(D34:F34) -> 1132 | D34: 615 | E34: 238 | F34: 279 | G34: 1 | H34: 0.54328622 | I34: 0.21024735 | J34: 0.24646643
A35: Miller-Trouba | B35: NYR | C35: =SUM(D35:F35) -> 1064 | D35: 564 | E35: 224 | F35: 276 | G35: 1 | H35: 0.53007519 | I35: 0.21052632 | J35: 0.2593985
A36: Nurse-Ceci | B36: EDM | C36: =SUM(D36:F36) -> 999 | D36: 538 | E36: 211 | F36: 250 | G36: 1 | H36: 0.53853854 | I36: 0.21121121 | J36: 0.25025025
A37: Middleton-Spurgeon | B37: MIN | C37: =SUM(D37:F37) -> 976 | D37: 476 | E37: 240 | F37: 260 | G37: 1 | H37: 0.48770492 | I37: 0.24590164 | J37: 0.26639344
A38: Lindell-Hakanp | B38: DAL | C38: =SUM(D38:F38) -> 866 | D38: 456 | E38: 162 | F38: 248 | G38: 1 | H38: 0.52655889 | I38: 0.18706697 | J38: 0.28637413
A39: Leddy-Parayko | B39: STL | C39: =SUM(D39:F39) -> 792 | D39: 414 | E39: 174 | F39: 204 | G39: 1 | H39: 0.52272727 | I39: 0.21969697 | J39: 0.25757576
A41: name | B41: team | C41: shotsattemptsfor | D41: shotsongoalfor | E41: missedshotsfor | F41: blockedshotattemptsfor
A42: Slavin-Burns | B42: CAR | C42: =SUM(D42:F42) -> 1 | D42: =D30/C30 -> 0.4972863 | E42: =E30/C30 -> 0.2421981 | F42: =F30/C30 -> 0.2605156
A43: Skjei-Pesce | B43: CAR | C43: =SUM(D43:F43) -> 1 | D43: =D31/C31 -> 0.51118881 | E43: =E31/C31 -> 0.24615385 | F43: =F31/C31 -> 0.24265734
A44: Dunn-Larsson | B44: SEA | C44: =SUM(D44:F44) -> 1 | D44: =D32/C32 -> 0.50907771 | E44: =E32/C32 -> 0.2432825 | F44: =F32/C32 -> 0.2476398
A45: Anderson-Doughty | B45: LAK | C45: =SUM(D45:F45) -> 1 | D45: =D33/C33 -> 0.54428203 | E45: =E33/C33 -> 0.20636285 | F45: =F33/C33 -> 0.24935512
A46: Siegenthaler-Hamilton | B46: NJD | C46: =SUM(D46:F46) -> 1 | D46: =D34/C34 -> 0.54328622 | E46: =E34/C34 -> 0.21024735 | F46: =F34/C34 -> 0.24646643
A47: Miller-Trouba | B47: NYR | C47: =SUM(D47:F47) -> 1 | D47: =D35/C35 -> 0.53007519 | E47: =E35/C35 -> 0.21052632 | F47: =F35/C35 -> 0.2593985
...
